[2022-03-08 14:35:54,095][Thread-1:18644][task_id:django.request][log.py:222][ERROR][Internal Server Error: /]
Traceback (most recent call last):
  File "D:\django_blog-master\django_blog-master\venv\lib\site-packages\django\core\handlers\exception.py", line 34, in inner
    response = get_response(request)
  File "D:\django_blog-master\django_blog-master\venv\lib\site-packages\django\core\handlers\base.py", line 115, in _get_response
    response = self.process_exception_by_middleware(e, request)
  File "D:\django_blog-master\django_blog-master\venv\lib\site-packages\django\core\handlers\base.py", line 113, in _get_response
    response = wrapped_callback(request, *callback_args, **callback_kwargs)
  File "D:\django_blog-master\django_blog-master\mysite\views.py", line 17, in index
    logger.info(str(RedisConnection.get('hotarticle').__dict__))
AttributeError: 'bytes' object has no attribute '__dict__'
[2022-03-08 14:36:51,149][Thread-1:21320][task_id:django.request][log.py:222][ERROR][Internal Server Error: /]
Traceback (most recent call last):
  File "D:\django_blog-master\django_blog-master\venv\lib\site-packages\django\core\handlers\exception.py", line 34, in inner
    response = get_response(request)
  File "D:\django_blog-master\django_blog-master\venv\lib\site-packages\django\core\handlers\base.py", line 115, in _get_response
    response = self.process_exception_by_middleware(e, request)
  File "D:\django_blog-master\django_blog-master\venv\lib\site-packages\django\core\handlers\base.py", line 113, in _get_response
    response = wrapped_callback(request, *callback_args, **callback_kwargs)
  File "D:\django_blog-master\django_blog-master\mysite\views.py", line 17, in index
    logger.info(str(RedisConnection.get('hotarticle').encode("utf-8")))
AttributeError: 'bytes' object has no attribute 'encode'
[2022-03-08 14:37:03,417][Thread-1:3244][task_id:django.request][log.py:222][ERROR][Internal Server Error: /]
Traceback (most recent call last):
  File "D:\django_blog-master\django_blog-master\venv\lib\site-packages\django\core\handlers\exception.py", line 34, in inner
    response = get_response(request)
  File "D:\django_blog-master\django_blog-master\venv\lib\site-packages\django\core\handlers\base.py", line 115, in _get_response
    response = self.process_exception_by_middleware(e, request)
  File "D:\django_blog-master\django_blog-master\venv\lib\site-packages\django\core\handlers\base.py", line 113, in _get_response
    response = wrapped_callback(request, *callback_args, **callback_kwargs)
  File "D:\django_blog-master\django_blog-master\mysite\views.py", line 17, in index
    logger.info(str(RedisConnection.get('hotarticle').decode("utf-8")))
UnicodeDecodeError: 'utf-8' codec can't decode byte 0x80 in position 0: invalid start byte
[2022-03-08 22:40:22,061][Thread-1:3296][task_id:django.request][log.py:222][ERROR][Internal Server Error: /]
Traceback (most recent call last):
  File "D:\django_blog-master\django_blog-master\venv\lib\site-packages\django\core\handlers\exception.py", line 34, in inner
    response = get_response(request)
  File "D:\django_blog-master\django_blog-master\venv\lib\site-packages\django\core\handlers\base.py", line 115, in _get_response
    response = self.process_exception_by_middleware(e, request)
  File "D:\django_blog-master\django_blog-master\venv\lib\site-packages\django\core\handlers\base.py", line 113, in _get_response
    response = wrapped_callback(request, *callback_args, **callback_kwargs)
  File "D:\django_blog-master\django_blog-master\mysite\views.py", line 15, in index
    RedisConnection = get_redis_connection('default')
  File "D:\django_blog-master\django_blog-master\venv\lib\site-packages\django_redis\__init__.py", line 15, in get_redis_connection
    raise NotImplementedError("This backend does not support this feature")
NotImplementedError: This backend does not support this feature
[2022-03-08 22:43:16,993][Thread-1:13416][task_id:django.request][log.py:222][ERROR][Internal Server Error: /]
Traceback (most recent call last):
  File "D:\django_blog-master\django_blog-master\venv\lib\site-packages\django\core\handlers\exception.py", line 34, in inner
    response = get_response(request)
  File "D:\django_blog-master\django_blog-master\venv\lib\site-packages\django\core\handlers\base.py", line 115, in _get_response
    response = self.process_exception_by_middleware(e, request)
  File "D:\django_blog-master\django_blog-master\venv\lib\site-packages\django\core\handlers\base.py", line 113, in _get_response
    response = wrapped_callback(request, *callback_args, **callback_kwargs)
  File "D:\django_blog-master\django_blog-master\mysite\views.py", line 16, in index
    logger.info(len(pickle.loads(get_redis_connection('default').get('hotarticle'))))
  File "D:\django_blog-master\django_blog-master\venv\lib\site-packages\django_redis\__init__.py", line 15, in get_redis_connection
    raise NotImplementedError("This backend does not support this feature")
NotImplementedError: This backend does not support this feature
[2022-03-08 22:45:01,921][Thread-1:13416][task_id:django.request][log.py:222][ERROR][Internal Server Error: /]
Traceback (most recent call last):
  File "D:\django_blog-master\django_blog-master\venv\lib\site-packages\django\core\handlers\exception.py", line 34, in inner
    response = get_response(request)
  File "D:\django_blog-master\django_blog-master\venv\lib\site-packages\django\core\handlers\base.py", line 115, in _get_response
    response = self.process_exception_by_middleware(e, request)
  File "D:\django_blog-master\django_blog-master\venv\lib\site-packages\django\core\handlers\base.py", line 113, in _get_response
    response = wrapped_callback(request, *callback_args, **callback_kwargs)
  File "D:\django_blog-master\django_blog-master\mysite\views.py", line 16, in index
    logger.info(len(pickle.loads(get_redis_connection('default').get('hotarticle'))))
  File "D:\django_blog-master\django_blog-master\venv\lib\site-packages\django_redis\__init__.py", line 15, in get_redis_connection
    raise NotImplementedError("This backend does not support this feature")
NotImplementedError: This backend does not support this feature
[2022-03-08 22:47:42,463][Thread-1:12748][task_id:django.request][log.py:222][ERROR][Internal Server Error: /]
Traceback (most recent call last):
  File "D:\django_blog-master\django_blog-master\venv\lib\site-packages\django\core\handlers\exception.py", line 34, in inner
    response = get_response(request)
  File "D:\django_blog-master\django_blog-master\venv\lib\site-packages\django\core\handlers\base.py", line 115, in _get_response
    response = self.process_exception_by_middleware(e, request)
  File "D:\django_blog-master\django_blog-master\venv\lib\site-packages\django\core\handlers\base.py", line 113, in _get_response
    response = wrapped_callback(request, *callback_args, **callback_kwargs)
  File "D:\django_blog-master\django_blog-master\mysite\views.py", line 16, in index
    logger.info(len(pickle.loads(get_redis_connection('default').get('hotarticle'))))
TypeError: a bytes-like object is required, not 'NoneType'
[2022-03-08 22:47:43,470][Thread-1:12748][task_id:django.request][log.py:222][ERROR][Internal Server Error: /]
Traceback (most recent call last):
  File "D:\django_blog-master\django_blog-master\venv\lib\site-packages\django\core\handlers\exception.py", line 34, in inner
    response = get_response(request)
  File "D:\django_blog-master\django_blog-master\venv\lib\site-packages\django\core\handlers\base.py", line 115, in _get_response
    response = self.process_exception_by_middleware(e, request)
  File "D:\django_blog-master\django_blog-master\venv\lib\site-packages\django\core\handlers\base.py", line 113, in _get_response
    response = wrapped_callback(request, *callback_args, **callback_kwargs)
  File "D:\django_blog-master\django_blog-master\mysite\views.py", line 16, in index
    logger.info(len(pickle.loads(get_redis_connection('default').get('hotarticle'))))
TypeError: a bytes-like object is required, not 'NoneType'
[2022-03-08 22:47:44,213][Thread-1:12748][task_id:django.request][log.py:222][ERROR][Internal Server Error: /]
Traceback (most recent call last):
  File "D:\django_blog-master\django_blog-master\venv\lib\site-packages\django\core\handlers\exception.py", line 34, in inner
    response = get_response(request)
  File "D:\django_blog-master\django_blog-master\venv\lib\site-packages\django\core\handlers\base.py", line 115, in _get_response
    response = self.process_exception_by_middleware(e, request)
  File "D:\django_blog-master\django_blog-master\venv\lib\site-packages\django\core\handlers\base.py", line 113, in _get_response
    response = wrapped_callback(request, *callback_args, **callback_kwargs)
  File "D:\django_blog-master\django_blog-master\mysite\views.py", line 16, in index
    logger.info(len(pickle.loads(get_redis_connection('default').get('hotarticle'))))
TypeError: a bytes-like object is required, not 'NoneType'
[2022-03-09 20:42:37,658][Thread-1:18732][task_id:django.request][log.py:222][ERROR][Internal Server Error: /]
Traceback (most recent call last):
  File "D:\django_blog-master\django_blog-master\venv\lib\site-packages\django\core\handlers\exception.py", line 34, in inner
    response = get_response(request)
TypeError: 'FileSystemFinder' object is not callable
